Hallo,

[% IF history -%]
der folgende Hintergrundjob ist bei kivitendo f端r den Mandanten [% client.name %] fehlgeschlagen:

Paketname:  [% history.package_name %]
Ausgef端hrt: [% history.run_at_as_timestamp %]
Fehler:     [% history.error_col %]

[% ELSE -%]
bei der Ausf端hrung des Task-Servers f端r den Mandanten [% client.name %] trat die folgende Ausnahme auf:

[% exception %]
[% END -%]
MfG,
kivitendo Task-Server
